Traceback (most recent call last):
  File "/home/adam/.local/lib/python3.7/site-packages/jupyter_cache/executors/utils.py", line 56, in single_nb_execution
    record_timing=False,
  File "/home/adam/.local/lib/python3.7/site-packages/nbclient/client.py", line 1087, in execute
    return NotebookClient(nb=nb, resources=resources, km=km, **kwargs).execute()
  File "/home/adam/.local/lib/python3.7/site-packages/nbclient/util.py", line 74, in wrapped
    return just_run(coro(*args, **kwargs))
  File "/home/adam/.local/lib/python3.7/site-packages/nbclient/util.py", line 53, in just_run
    return loop.run_until_complete(coro)
  File "/home/adam/anaconda3/lib/python3.7/asyncio/base_events.py", line 584, in run_until_complete
    return future.result()
  File "/home/adam/.local/lib/python3.7/site-packages/nbclient/client.py", line 541, in async_execute
    cell, index, execution_count=self.code_cells_executed + 1
  File "/home/adam/.local/lib/python3.7/site-packages/nbclient/client.py", line 832, in async_execute_cell
    self._check_raise_for_error(cell, exec_reply)
  File "/home/adam/.local/lib/python3.7/site-packages/nbclient/client.py", line 740, in _check_raise_for_error
    raise CellExecutionError.from_cell_and_msg(cell, exec_reply['content'])
nbclient.exceptions.CellExecutionError: An error occurred while executing the following cell:
------------------
agg_cluster_A = AgglomerativeClustering().fit(df_orl[["A+", "A-"]])
df_orl.plot.scatter("A+", "A-", c=agg_cluster_A.labels_, cmap="Set1")
plt.set_xlabel("A+")
plt.show()
------------------

[0;31m---------------------------------------------------------------------------[0m
[0;31mAttributeError[0m                            Traceback (most recent call last)
[0;32m<ipython-input-6-f4ef16cced7f>[0m in [0;36m<module>[0;34m[0m
[1;32m      1[0m [0magg_cluster_A[0m [0;34m=[0m [0mAgglomerativeClustering[0m[0;34m([0m[0;34m)[0m[0;34m.[0m[0mfit[0m[0;34m([0m[0mdf_orl[0m[0;34m[[0m[0;34m[[0m[0;34m"A+"[0m[0;34m,[0m [0;34m"A-"[0m[0;34m][0m[0;34m][0m[0;34m)[0m[0;34m[0m[0;34m[0m[0m
[1;32m      2[0m [0mdf_orl[0m[0;34m.[0m[0mplot[0m[0;34m.[0m[0mscatter[0m[0;34m([0m[0;34m"A+"[0m[0;34m,[0m [0;34m"A-"[0m[0;34m,[0m [0mc[0m[0;34m=[0m[0magg_cluster_A[0m[0;34m.[0m[0mlabels_[0m[0;34m,[0m [0mcmap[0m[0;34m=[0m[0;34m"Set1"[0m[0;34m)[0m[0;34m[0m[0;34m[0m[0m
[0;32m----> 3[0;31m [0mplt[0m[0;34m.[0m[0mset_xlabel[0m[0;34m([0m[0;34m"A+"[0m[0;34m)[0m[0;34m[0m[0;34m[0m[0m
[0m[1;32m      4[0m [0mplt[0m[0;34m.[0m[0mshow[0m[0;34m([0m[0;34m)[0m[0;34m[0m[0;34m[0m[0m

[0;31mAttributeError[0m: module 'matplotlib.pyplot' has no attribute 'set_xlabel'
AttributeError: module 'matplotlib.pyplot' has no attribute 'set_xlabel'

